<?xml version="1.0" encoding="utf-8"?>
<sdf version="1.9">
  <model name="X3">
    <static>false</static>
    <!-- Model-level <pose> removed: not supported by sdformat_urdf (robot_state_publisher). Offset baked into base_link. -->
    <link name="X3/base_link">
      <pose>0 0 0.053302 0 0 0</pose>
      <inertial>
        <pose>0 0 0 0 0 0</pose>
        <mass>1.5</mass>
        <inertia>
          <ixx>0.0347563</ixx>
          <ixy>0</ixy>
          <ixz>0</ixz>
          <iyy>0.07</iyy>
          <iyz>0</iyz>
          <izz>0.0977</izz>
        </inertia>
      </inertial>
      <collision name="X3/base_link_inertia_collision">
        <pose>0 0 0 0 0 0</pose>
        <geometry>
          <box>
            <size>0.47 0.47 0.11</size>
          </box>
        </geometry>
      </collision>
      <visual name="X3/base_link_inertia_visual">
        <pose>0 0 0 0 0 0</pose>
        <geometry>
          <mesh>
            <uri>model://X3/meshes/x3.dae</uri>
            <scale>1 1 1</scale>
          </mesh>
        </geometry>
      </visual>
      <sensor name="imu_sensor" type="imu">
        <always_on>1</always_on>
        <update_rate>200</update_rate>
        <visualize>false</visualize>
        <topic>imu</topic>
        <frame>X3/base_link</frame>
        <imu>
          <angular_velocity>
            <x>
              <noise type="gaussian">
                <mean>0.0</mean>
                <stddev>0.0002</stddev>
              </noise>
            </x>
            <y>
              <noise type="gaussian">
                <mean>0.0</mean>
                <stddev>0.0002</stddev>
              </noise>
            </y>
            <z>
              <noise type="gaussian">
                <mean>0.0</mean>
                <stddev>0.0002</stddev>
              </noise>
            </z>
          </angular_velocity>
          <linear_acceleration>
            <x>
              <noise type="gaussian">
                <mean>0.0</mean>
                <stddev>0.017</stddev>
              </noise>
            </x>
            <y>
              <noise type="gaussian">
                <mean>0.0</mean>
                <stddev>0.017</stddev>
              </noise>
            </y>
            <z>
              <noise type="gaussian">
                <mean>0.0</mean>
                <stddev>0.017</stddev>
              </noise>
            </z>
          </linear_acceleration>
        </imu>
      </sensor>
    </link>

    <link name="X3/rotor_0">
      <pose>0.13 -0.22 0.023 0 0 0</pose>
      <inertial>
        <mass>0.005</mass>
        <inertia>
          <ixx>9.75e-07</ixx>
          <ixy>0</ixy>
          <ixz>0</ixz>
          <iyy>4.17041e-05</iyy>
          <iyz>0</iyz>
          <izz>4.26041e-05</izz>
        </inertia>
      </inertial>
      <collision name="X3/rotor_0_collision">
        <geometry>
          <cylinder>
            <length>0.005</length>
            <radius>0.1</radius>
          </cylinder>
        </geometry>
      </collision>
      <visual name="X3/rotor_0_visual">
        <geometry>
          <mesh>
            <uri>model://X3/meshes/propeller_ccw.dae</uri>
            <scale>0.1 0.1 0.1</scale>
          </mesh>
        </geometry>
      </visual>
      <gravity>1</gravity>
      <velocity_decay/>
    </link>
    <joint name="X3/rotor_0_joint" type="revolute">
      <parent>X3/base_link</parent>
      <child>X3/rotor_0</child>
      <axis>
        <xyz>0 0 1</xyz>
        <limit>
          <lower>-1e16</lower>
          <upper>1e16</upper>
        </limit>
        <dynamics>
          <spring_reference>0</spring_reference>
          <spring_stiffness>0</spring_stiffness>
        </dynamics>
        <use_parent_model_frame>1</use_parent_model_frame>
      </axis>
    </joint>

    <link name="X3/rotor_1">
      <pose>-0.13 0.2 0.023 0 0 0</pose>
      <inertial>
        <mass>0.005</mass>
        <inertia>
          <ixx>9.75e-07</ixx>
          <ixy>0</ixy>
          <ixz>0</ixz>
          <iyy>4.17041e-05</iyy>
          <iyz>0</iyz>
          <izz>4.26041e-05</izz>
        </inertia>
      </inertial>
      <collision name="X3/rotor_1_collision">
        <geometry>
          <cylinder>
            <length>0.005</length>
            <radius>0.1</radius>
          </cylinder>
        </geometry>
      </collision>
      <visual name="X3/rotor_1_visual">
        <geometry>
          <mesh>
            <uri>model://X3/meshes/propeller_ccw.dae</uri>
            <scale>0.1 0.1 0.1</scale>
          </mesh>
        </geometry>
      </visual>
      <gravity>1</gravity>
      <velocity_decay/>
    </link>
    <joint name="X3/rotor_1_joint" type="revolute">
      <parent>X3/base_link</parent>
      <child>X3/rotor_1</child>
      <axis>
        <xyz>0 0 1</xyz>
        <limit>
          <lower>-1e16</lower>
          <upper>1e16</upper>
        </limit>
        <dynamics>
          <spring_reference>0</spring_reference>
          <spring_stiffness>0</spring_stiffness>
        </dynamics>
        <use_parent_model_frame>1</use_parent_model_frame>
      </axis>
    </joint>

    <link name="X3/rotor_2">
      <pose>0.13 0.22 0.023 0 0 0</pose>
      <inertial>
        <mass>0.005</mass>
        <inertia>
          <ixx>9.75e-07</ixx>
          <ixy>0</ixy>
          <ixz>0</ixz>
          <iyy>4.17041e-05</iyy>
          <iyz>0</iyz>
          <izz>4.26041e-05</izz>
        </inertia>
      </inertial>
      <collision name="X3/rotor_2_collision">
        <geometry>
          <cylinder>
            <length>0.005</length>
            <radius>0.1</radius>
          </cylinder>
        </geometry>
      </collision>
      <visual name="X3/rotor_2_visual">
        <geometry>
          <mesh>
            <uri>model://X3/meshes/propeller_cw.dae</uri>
            <scale>0.1 0.1 0.1</scale>
          </mesh>
        </geometry>
      </visual>
      <gravity>1</gravity>
      <velocity_decay/>
    </link>
    <joint name="X3/rotor_2_joint" type="revolute">
      <parent>X3/base_link</parent>
      <child>X3/rotor_2</child>
      <axis>
        <xyz>0 0 1</xyz>
        <limit>
          <lower>-1e16</lower>
          <upper>1e16</upper>
        </limit>
        <dynamics>
          <spring_reference>0</spring_reference>
          <spring_stiffness>0</spring_stiffness>
        </dynamics>
        <use_parent_model_frame>1</use_parent_model_frame>
      </axis>
    </joint>

    <link name="X3/rotor_3">
      <pose>-0.13 -0.22 0.023 0 0 0</pose>
      <inertial>
        <mass>0.005</mass>
        <inertia>
          <ixx>9.75e-07</ixx>
          <ixy>0</ixy>
          <ixz>0</ixz>
          <iyy>4.17041e-05</iyy>
          <iyz>0</iyz>
          <izz>4.26041e-05</izz>
        </inertia>
      </inertial>
      <collision name="X3/rotor_3_collision">
        <geometry>
          <cylinder>
            <length>0.005</length>
            <radius>0.1</radius>
          </cylinder>
        </geometry>
      </collision>
      <visual name="X3/rotor_3_visual">
        <geometry>
          <mesh>
            <uri>model://X3/meshes/propeller_cw.dae</uri>
            <scale>0.1 0.1 0.1</scale>
          </mesh>
        </geometry>
      </visual>
      <gravity>1</gravity>
      <velocity_decay/>
    </link>
    <joint name="X3/rotor_3_joint" type="revolute">
      <parent>X3/base_link</parent>
      <child>X3/rotor_3</child>
      <axis>
        <xyz>0 0 1</xyz>
        <limit>
          <lower>-1e16</lower>
          <upper>1e16</upper>
        </limit>
        <dynamics>
          <spring_reference>0</spring_reference>
          <spring_stiffness>0</spring_stiffness>
        </dynamics>
        <use_parent_model_frame>1</use_parent_model_frame>
      </axis>
    </joint>

    <!-- Camera link (extrinsics: imu^T_cam, imu^R_cam from VINS config; pose = camera in base/IMU frame) -->
    <link name="X3/camera_link">
      <pose>-0.0015 0.00604 0.0623 0.0 -0.523599 0.0</pose>
      <inertial>
        <mass>0.02</mass>
        <inertia>
          <ixx>1e-06</ixx>
          <ixy>0</ixy>
          <ixz>0</ixz>
          <iyy>1e-06</iyy>
          <iyz>0</iyz>
          <izz>1e-06</izz>
        </inertia>
      </inertial>
      <visual name="X3/camera_visual">
        <geometry>
          <box>
            <size>0.02 0.04 0.02</size>
          </box>
        </geometry>
      </visual>
      <sensor name="camera" type="camera">
        <camera>
          <horizontal_fov>1.309</horizontal_fov>
          <vertical_fov>1.0472</vertical_fov>
          <image>
            <width>1280</width>
            <height>720</height>
          </image>
          <clip>
            <near>0.05</near>
            <far>50</far>
          </clip>
          <distortion>
            <k1>-0.25390268</k1>
            <k2>0.06240127</k2>
            <k3>0</k3>
            <p1>-0.00113674</p1>
            <p2>0.00213326</p2>
          </distortion>
          <!--
            Camera streams continuously at <update_rate> Hz. The MonoRace live
            perception node needs continuous frames, not triggered ones.

            FOR DATA GENERATION re-enable triggering (pencilnet_ros
            data_generator_node assumes a triggered camera):
              <triggered>true</triggered>
              <trigger_topic>/camera_trigger</trigger_topic>
          -->
        </camera>
        <always_on>1</always_on>
        <update_rate>30</update_rate>
        <topic>image_raw</topic>
        <frame>X3/camera_link</frame>
      </sensor>
      <sensor name="depth_camera" type="depth_camera">
        <camera>
          <horizontal_fov>1.309</horizontal_fov>
          <vertical_fov>1.0472</vertical_fov>
          <image>
            <width>1280</width>
            <height>720</height>
          </image>
          <clip>
            <near>0.05</near>
            <far>30</far>
          </clip>
          <!--
            Depth camera streams continuously. Re-enable triggering for data
            generation (see RGB camera comment above):
              <triggered>true</triggered>
              <trigger_topic>/camera_trigger</trigger_topic>
          -->
        </camera>
        <always_on>1</always_on>
        <update_rate>30</update_rate>
        <topic>depth_image</topic>
        <frame>X3/camera_link</frame>
      </sensor>
    </link>
    <joint name="X3/camera_joint" type="fixed">
      <parent>X3/base_link</parent>
      <child>X3/camera_link</child>
    </joint>

    <plugin
      filename="gz-sim-multicopter-motor-model-system"
      name="gz::sim::systems::MulticopterMotorModel">
      <robotNamespace>X3</robotNamespace>
      <jointName>X3/rotor_0_joint</jointName>
      <linkName>X3/rotor_0</linkName>
      <turningDirection>ccw</turningDirection>
      <timeConstantUp>0.0125</timeConstantUp>
      <timeConstantDown>0.025</timeConstantDown>
      <maxRotVelocity>800.0</maxRotVelocity>
      <motorConstant>8.54858e-06</motorConstant>
      <momentConstant>0.016</momentConstant>
      <commandSubTopic>gazebo/command/motor_speed</commandSubTopic>
      <motorNumber>0</motorNumber>
      <rotorDragCoefficient>8.06428e-05</rotorDragCoefficient>
      <rollingMomentCoefficient>1e-06</rollingMomentCoefficient>
      <motorSpeedPubTopic>motor_speed/0</motorSpeedPubTopic>
      <rotorVelocitySlowdownSim>10</rotorVelocitySlowdownSim>
      <motorType>velocity</motorType>
    </plugin>
    <plugin
      filename="gz-sim-multicopter-motor-model-system"
      name="gz::sim::systems::MulticopterMotorModel">
      <robotNamespace>X3</robotNamespace>
      <jointName>X3/rotor_1_joint</jointName>
      <linkName>X3/rotor_1</linkName>
      <turningDirection>ccw</turningDirection>
      <timeConstantUp>0.0125</timeConstantUp>
      <timeConstantDown>0.025</timeConstantDown>
      <maxRotVelocity>800.0</maxRotVelocity>
      <motorConstant>8.54858e-06</motorConstant>
      <momentConstant>0.016</momentConstant>
      <commandSubTopic>gazebo/command/motor_speed</commandSubTopic>
      <motorNumber>1</motorNumber>
      <rotorDragCoefficient>8.06428e-05</rotorDragCoefficient>
      <rollingMomentCoefficient>1e-06</rollingMomentCoefficient>
      <motorSpeedPubTopic>motor_speed/1</motorSpeedPubTopic>
      <rotorVelocitySlowdownSim>10</rotorVelocitySlowdownSim>
      <motorType>velocity</motorType>
    </plugin>
    <plugin
      filename="gz-sim-multicopter-motor-model-system"
      name="gz::sim::systems::MulticopterMotorModel">
      <robotNamespace>X3</robotNamespace>
      <jointName>X3/rotor_2_joint</jointName>
      <linkName>X3/rotor_2</linkName>
      <turningDirection>cw</turningDirection>
      <timeConstantUp>0.0125</timeConstantUp>
      <timeConstantDown>0.025</timeConstantDown>
      <maxRotVelocity>800.0</maxRotVelocity>
      <motorConstant>8.54858e-06</motorConstant>
      <momentConstant>0.016</momentConstant>
      <commandSubTopic>gazebo/command/motor_speed</commandSubTopic>
      <motorNumber>2</motorNumber>
      <rotorDragCoefficient>8.06428e-05</rotorDragCoefficient>
      <rollingMomentCoefficient>1e-06</rollingMomentCoefficient>
      <motorSpeedPubTopic>motor_speed/2</motorSpeedPubTopic>
      <rotorVelocitySlowdownSim>10</rotorVelocitySlowdownSim>
      <motorType>velocity</motorType>
    </plugin>
    <plugin
      filename="gz-sim-multicopter-motor-model-system"
      name="gz::sim::systems::MulticopterMotorModel">
      <robotNamespace>X3</robotNamespace>
      <jointName>X3/rotor_3_joint</jointName>
      <linkName>X3/rotor_3</linkName>
      <turningDirection>cw</turningDirection>
      <timeConstantUp>0.0125</timeConstantUp>
      <timeConstantDown>0.025</timeConstantDown>
      <maxRotVelocity>800.0</maxRotVelocity>
      <motorConstant>8.54858e-06</motorConstant>
      <momentConstant>0.016</momentConstant>
      <commandSubTopic>gazebo/command/motor_speed</commandSubTopic>
      <motorNumber>3</motorNumber>
      <rotorDragCoefficient>8.06428e-05</rotorDragCoefficient>
      <rollingMomentCoefficient>1e-06</rollingMomentCoefficient>
      <motorSpeedPubTopic>motor_speed/3</motorSpeedPubTopic>
      <rotorVelocitySlowdownSim>10</rotorVelocitySlowdownSim>
      <motorType>velocity</motorType>
    </plugin>
    <plugin
      filename="gz-sim-multicopter-control-system"
      name="gz::sim::systems::MulticopterVelocityControl">
      <robotNamespace>X3</robotNamespace>
      <commandSubTopic>cmd_vel</commandSubTopic>
      <enableSubTopic>enable</enableSubTopic>
      <comLinkName>X3/base_link</comLinkName>
      <velocityGain>2.7 2.7 2.7</velocityGain>
      <attitudeGain>2 3 0.15</attitudeGain>
      <angularRateGain>0.4 0.52 0.18</angularRateGain>
      <maximumLinearAcceleration>2 2 2</maximumLinearAcceleration>

      <rotorConfiguration>
        <rotor>
          <jointName>X3/rotor_0_joint</jointName>
          <forceConstant>8.54858e-06</forceConstant>
          <momentConstant>0.016</momentConstant>
          <direction>1</direction>
        </rotor>
        <rotor>
          <jointName>X3/rotor_1_joint</jointName>
          <forceConstant>8.54858e-06</forceConstant>
          <momentConstant>0.016</momentConstant>
          <direction>1</direction>
        </rotor>
        <rotor>
          <jointName>X3/rotor_2_joint</jointName>
          <forceConstant>8.54858e-06</forceConstant>
          <momentConstant>0.016</momentConstant>
          <direction>-1</direction>
        </rotor>
        <rotor>
          <jointName>X3/rotor_3_joint</jointName>
          <forceConstant>8.54858e-06</forceConstant>
          <momentConstant>0.016</momentConstant>
          <direction>-1</direction>
        </rotor>
      </rotorConfiguration>
    </plugin>
    <plugin
      filename="libignition-gazebo-odometry-publisher-system.so"
      name="ignition::gazebo::systems::OdometryPublisher">
      <odom_frame>odom</odom_frame>
      <robot_base_frame>X3/base_link</robot_base_frame>
      <odom_topic>odom</odom_topic>
      <dimensions>3</dimensions>
    </plugin>
  </model>
</sdf>
